{"is_correct": false, "reason": "This git diff is **false** because it incorrectly handles the case where a symbolic link points outside the root directory.\n\n**The main issue is with the exception handling logic:**\n\nThe code catches a `ValueError` exception and assumes it's always due to a symbolic link pointing outside the root directory. However, the `ValueError` is thrown by `child.resolve().relative_to(root)` which could occur for **any** path that doesn't start with the root directory, not just symbolic links.\n\n**Specific problems:**\n\n1. **Incorrect assumption**: The code assumes that any `ValueError` from `relative_to()` means the file is a symbolic link pointing outside the root. This is wrong - the `ValueError` could be thrown for regular files or directories that are outside the root for other reasons.\n\n2. **Wrong order of operations**: The code calls `child.resolve()` first, then checks if it's a symlink. But `resolve()` follows the symlink, so `child.is_symlink()` will check the original path, not the resolved path that caused the error.\n\n3. **Logic gap**: If a non-symlink file somehow ends up outside the root directory and causes a `ValueError`, the code will still check `child.is_symlink()`, find it's not a symlink, and then re-raise the exception. This could mask the real issue.\n\n**The correct approach should be:**\n1. Check if the child is a symlink BEFORE resolving it\n2. If it's a symlink, resolve it and check if the resolved path is outside the root\n3. Only then decide whether to ignore it or process it\n\nThe current implementation creates a logical flaw where any `ValueError` is treated as a potential symlink issue, which is not accurate."}
